Workbook
Name beta1: FLI!$R$25
Name beta2: FLI!$R$26
Name beta3: FLI!$R$27
Name factor: FLI!$E$89
Name intercept: FLI!$R$24

Sheet Instruction
C5: Hello User,
C7: The building of this model has been divided into 4 parts namely
C8: - Exposure at Default
C9: - Probability of Default
C10: - Loss Given Default
C11: - Forward-Looking Information
C13: These three parameters will determine the building of Expected Credit Losses for Trade Receivables
C15: In the course of building the software app, read and study this excel well.
C17: Regards,
C18: Olamide A.

Sheet Requirement (EAD)
D3: Exposure at Default Calculation (Part of Impairment Studio)
D6: A. For Trade Receivables: EAD = Outstanding Receivable Balance
D7: But a robust model must answer:
D8: What is the exposure?
D9: Where is the risk concentrated?
D10: How does exposure behave over time?
D11: Which segments drive risk?
D12: Is aging deteriorating?
D13: So EAD module = Exposure Measurement + Risk Analytics
D16: B. Information Requirements for EAD
D17: Core Dataset — AR Ledger (Mandatory)
D19: Field | E19: Description | F19: Example | G19: Why Needed
D20: Customer ID | E20: Unique ID | F20: C001 | G20: Customer analysis | O20: Steps to follow in general
D21: Customer Name | E21: Customer name | F21: ABC Stores | G21: Reporting | O21: a. Upload EAD data in the data manager module. This data is called Trade Receivables Balances
D22: Invoice No | E22: Invoice reference | F22: INV1001 | G22: Traceability | O22: b. In the EAD module, make sure you show the EAD Engine… both in table and in graph
D23: Invoice Date | E23: Date issued | F23: 45658 | G23: Aging trend | O23: Also in the EAD module, make sure you have the analysis
D24: Due Date | E24: Payment due | F24: 45688 | G24: Aging calculation
D25: Outstanding Amount | E25: Balance | F25: 2500000 | G25: EAD
D26: Segment | E26: Distributor/Retailer | F26: Distributor | G26: Segmentation
D27: Region | E27: Geographic region | F27: Lagos | G27: Concentration
D28: Product Type | E28: Flour/Rice etc | F28: Flour | G28: Risk drivers
D29: Credit Limit | E29: Customer limit | F29: 10m | G29: Utilization
D30: Currency | E30: NGN/USD | F30: NGN | G30: FX exposure
D33: C. Derived Fields (To be calculated and show in the EAD module)
D36: Field | E36: Formula | F36: Purpose
D37: Days Past Due | E37: Today – DueDate | F37: Aging
D38: Aging Bucket | E38: IF formula | F38: Provision matrix
D39: Exposure Share | E39: Balance/Total | F39: Concentration
D40: Utilization | E40: Balance/CreditLimit | F40: Credit risk
D41: Invoice Size Band | E41: IF formula | F41: Granularity
D44: D. With the above information your EAD is ready to go

Sheet EAD Engine
D3: Exposure at Default Calculation (Part of Impairment Studio)
D6: Customer ID | E6: Customer Name | F6: Invoice No | G6: Invoice Date | H6: Due Date | I6: Outstanding Amount | J6: Segment | K6: Region | L6: Product Type | M6: Credit Limit | N6: Days Past Due | O6: Aging Bucket | P6: Exposure Share | Q6: Utilization | R6: Aging Bucket
D7: C179 | E7: Customer_179 | F7: INV77671 | G7: 45797 | H7: 46090 | I7: 40000000 | J7: Distributor | K7: Kano | L7: Product Type 2 | M7: 280000000 | N7: =MAX(0,TODAY()-H7) -> 0 | O7: =IF(N7<=0,"Current", IF(N7<=30,"1-30", IF(N7<=60,"31-60", IF(N7<=90,"61-90","90+")))) -> Current | P7: =I7/SUM($I$7:$I$438) -> 0.0064156161 | Q7: =I7/M7 -> 0.14285714 | R7: =IF(I7<500000,"<500K", IF(I7<2000000,"500K-2M", IF(I7<5000000,"2M-5M",">5M"))) -> >5M
D8: C064 | E8: Customer_064 | F8: INV13665 | G8: 45826 | H8: 46038 | I8: 6773687 | J8: Distributor | K8: Port Harcourt | L8: Product Type 4 | M8: 47415809 | N8: =MAX(0,TODAY()-H8) -> 45 | O8: =IF(N8<=0,"Current", IF(N8<=30,"1-30", IF(N8<=60,"31-60", IF(N8<=90,"61-90","90+")))) -> 31-60 | P8: =I8/SUM($I$7:$I$438) -> 0.0010864344 | Q8: =I8/M8 -> 0.14285714 | R8: =IF(I8<500000,"<500K", IF(I8<2000000,"500K-2M", IF(I8<5000000,"2M-5M",">5M"))) -> >5M
D9: C149 | E9: Customer_149 | F9: INV37150 | G9: 46022 | H9: 46004 | I9: 7857221 | J9: Retailer | K9: Kano | L9: Product Type 2 | M9: 62857768 | N9: =MAX(0,TODAY()-H9) -> 79 | O9: =IF(N9<=0,"Current", IF(N9<=30,"1-30", IF(N9<=60,"31-60", IF(N9<=90,"61-90","90+")))) -> 61-90 | P9: =I9/SUM($I$7:$I$438) -> 0.0012602228 | Q9: =I9/M9 -> 0.125 | R9: =IF(I9<500000,"<500K", IF(I9<2000000,"500K-2M", IF(I9<5000000,"2M-5M",">5M"))) -> >5M
D10: C041 | E10: Customer_041 | F10: INV89622 | G10: 45720 | H10: 45936 | I10: 1426502 | J10: Distributor | K10: Port Harcourt | L10: Product Type 4 | M10: 4279506 | N10: =MAX(0,TODAY()-H10) -> 147 | O10: =IF(N10<=0,"Current", IF(N10<=30,"1-30", IF(N10<=60,"31-60", IF(N10<=90,"61-90","90+")))) -> 90+ | P10: =I10/SUM($I$7:$I$438) -> 0.00022879723 | Q10: =I10/M10 -> 0.33333333 | R10: =IF(I10<500000,"<500K", IF(I10<2000000,"500K-2M", IF(I10<5000000,"2M-5M",">5M"))) -> 500K-2M
D11: C017 | E11: Customer_017 | F11: INV65312 | G11: 45790 | H11: 46014 | I11: 179838 | J11: Distributor | K11: Kano | L11: Product Type 4 | M11: 719352 | N11: =MAX(0,TODAY()-H11) -> 69 | O11: =IF(N11<=0,"Current", IF(N11<=30,"1-30", IF(N11<=60,"31-60", IF(N11<=90,"61-90","90+")))) -> 61-90 | P11: =I11/SUM($I$7:$I$438) -> 2.8844289e-05 | Q11: =I11/M11 -> 0.25 | R11: =IF(I11<500000,"<500K", IF(I11<2000000,"500K-2M", IF(I11<5000000,"2M-5M",">5M"))) -> <500K
D12: C192 | E12: Customer_192 | F12: INV86095 | G12: 45973 | H12: 45916 | I12: 3334681 | J12: Distributor | K12: Abuja | L12: Product Type 5 | M12: 20008086 | N12: =MAX(0,TODAY()-H12) -> 167 | O12: =IF(N12<=0,"Current", IF(N12<=30,"1-30", IF(N12<=60,"31-60", IF(N12<=90,"61-90","90+")))) -> 90+ | P12: =I12/SUM($I$7:$I$438) -> 0.00053485083 | Q12: =I12/M12 -> 0.16666667 | R12: =IF(I12<500000,"<500K", IF(I12<2000000,"500K-2M", IF(I12<5000000,"2M-5M",">5M"))) -> 2M-5M
D13: C057 | E13: Customer_057 | F13: INV50639 | G13: 45899 | H13: 45968 | I13: 2466404 | J13: Distributor | K13: Kano | L13: Product Type 1 | M13: 4932808 | N13: =MAX(0,TODAY()-H13) -> 115 | O13: =IF(N13<=0,"Current", IF(N13<=30,"1-30", IF(N13<=60,"31-60", IF(N13<=90,"61-90","90+")))) -> 90+ | P13: =I13/SUM($I$7:$I$438) -> 0.00039558753 | Q13: =I13/M13 -> 0.5 | R13: =IF(I13<500000,"<500K", IF(I13<2000000,"500K-2M", IF(I13<5000000,"2M-5M",">5M"))) -> 2M-5M
D14: C073 | E14: Customer_073 | F14: INV11480 | G14: 46019 | H14: 45977 | I14: 7863875 | J14: Distributor | K14: Kano | L14: Product Type 5 | M14: 39319375 | N14: =MAX(0,TODAY()-H14) -> 106 | O14: =IF(N14<=0,"Current", IF(N14<=30,"1-30", IF(N14<=60,"31-60", IF(N14<=90,"61-90","90+")))) -> 90+ | P14: =I14/SUM($I$7:$I$438) -> 0.0012612901 | Q14: =I14/M14 -> 0.2 | R14: =IF(I14<500000,"<500K", IF(I14<2000000,"500K-2M", IF(I14<5000000,"2M-5M",">5M"))) -> >5M
D15: C170 | E15: Customer_170 | F15: INV73501 | G15: 45909 | H15: 45978 | I15: 7050710 | J15: Distributor | K15: Abuja | L15: Product Type 6 | M15: 56405680 | N15: =MAX(0,TODAY()-H15) -> 105 | O15: =IF(N15<=0,"Current", IF(N15<=30,"1-30", IF(N15<=60,"31-60", IF(N15<=90,"61-90","90+")))) -> 90+ | P15: =I15/SUM($I$7:$I$438) -> 0.0011308662 | Q15: =I15/M15 -> 0.125 | R15: =IF(I15<500000,"<500K", IF(I15<2000000,"500K-2M", IF(I15<5000000,"2M-5M",">5M"))) -> >5M
D16: C185 | E16: Customer_185 | F16: INV88619 | G16: 45968 | H16: 45987 | I16: 4851914 | J16: Distributor | K16: Ibadan | L16: Product Type 1 | M16: 48519140 | N16: =MAX(0,TODAY()-H16) -> 96 | O16: =IF(N16<=0,"Current", IF(N16<=30,"1-30", IF(N16<=60,"31-60", IF(N16<=90,"61-90","90+")))) -> 90+ | P16: =I16/SUM($I$7:$I$438) -> 0.00077820044 | Q16: =I16/M16 -> 0.1 | R16: =IF(I16<500000,"<500K", IF(I16<2000000,"500K-2M", IF(I16<5000000,"2M-5M",">5M"))) -> 2M-5M
D17: C197 | E17: Customer_197 | F17: INV68281 | G17: 45788 | H17: 45940 | I17: 5306932 | J17: Retailer | K17: Abuja | L17: Product Type 6 | M17: 42455456 | N17: =MAX(0,TODAY()-H17) -> 143 | O17: =IF(N17<=0,"Current", IF(N17<=30,"1-30", IF(N17<=60,"31-60", IF(N17<=90,"61-90","90+")))) -> 90+ | P17: =I17/SUM($I$7:$I$438) -> 0.00085118096 | Q17: =I17/M17 -> 0.125 | R17: =IF(I17<500000,"<500K", IF(I17<2000000,"500K-2M", IF(I17<5000000,"2M-5M",">5M"))) -> >5M
D18: C198 | E18: Customer_198 | F18: INV63279 | G18: 45998 | H18: 46091 | I18: 500000000 | J18: Retailer | K18: Abuja | L18: Product Type 2 | M18: 4000000000 | N18: =MAX(0,TODAY()-H18) -> 0 | O18: =IF(N18<=0,"Current", IF(N18<=30,"1-30", IF(N18<=60,"31-60", IF(N18<=90,"61-90","90+")))) -> Current | P18: =I18/SUM($I$7:$I$438) -> 0.080195201 | Q18: =I18/M18 -> 0.125 | R18: =IF(I18<500000,"<500K", IF(I18<2000000,"500K-2M", IF(I18<5000000,"2M-5M",">5M"))) -> >5M
... D438: C153 | E438: Customer_153 | F438: INV92874 | G438: 45968 | H438: 46122 | I438: 670000000 | J438: Distributor | K438: Abuja | L438: Product Type 6 | M438: 6030000000 | N438: =MAX(0,TODAY()-H438) -> 0 | O438: =IF(N438<=0,"Current", IF(N438<=30,"1-30", IF(N438<=60,"31-60", IF(N438<=90,"61-90","90+")))) -> Current | P438: =I438/SUM($I$7:$I$438) -> 0.10746157 | Q438: =I438/M438 -> 0.11111111 | R438: =IF(I438<500000,"<500K", IF(I438<2000000,"500K-2M", IF(I438<5000000,"2M-5M",">5M"))) -> >5M

Sheet EAD Analysis
B4: 1 | C4: Output 1 — Total Exposure
J6: Please let this look like the PD dashbaord we have for he main ECL app
B9: 2 | C9: Total Exposure by Aging Bucket
C11: Row Labels | D11: Exposure | F11: Row Labels | G11: Sum of Outstanding Amount
C12: 1-30 | D12: 249206509 | F12: Abuja | G12: 3163404513
C13: 31-60 | D13: 1895773951 | F13: Ibadan | G13: 447840616
C14: 61-90 | D14: 249973198 | F14: Kaduna | G14: 314929395
C15: 90+ | D15: 1929080135 | F15: Kano | G15: 339032098 | K15: This is the main output of the EAD process
C16: Current | D16: 1910753232 | F16: Lagos | G16: 681378207 | K16: Row Labels | L16: Exposure | M16: Sum of Exposure Share
C17: Grand Total | D17: 6234787025 | F17: Port Harcourt | G17: 1288202196 | K17: 1-30 | L17: 249206509 | M17: 0.039970332
F18: Grand Total | G18: 6234787025 | K18: 31-60 | L18: 1895773951 | M18: 0.30406395
K19: 61-90 | L19: 249973198 | M19: 0.040093302
K20: 90+ | L20: 1929080135 | M20: 0.30940594
B21: 3 | C21: Concentration Metrics | K21: Current | L21: 1910753232 | M21: 0.30646648
C22: Top 10 customers | K22: Grand Total | L22: 6234787025 | M22: 1
B24: 4 | C24: Invoice size distribution | K24: Your analysis can show performing analysis too
K25: Meaning that only current and 1 - 30 are perfoming exposure.
K26: the rest are non performing
K29: Row Labels | L29: Exposure
K30: Current | L30: =GETPIVOTDATA("Exposure",$K$16,"Aging Bucket","Current") -> 1910753232
K31: 1-30 | L31: =GETPIVOTDATA("Exposure",$K$16,"Aging Bucket","1-30") -> 249206509
K32: 31-60 | L32: =GETPIVOTDATA("Exposure",$K$16,"Aging Bucket","31-60") -> 1895773951
K33: 61-90 | L33: =GETPIVOTDATA("Exposure",$K$16,"Aging Bucket","61-90") -> 249973198
K34: 90+ | L34: =GETPIVOTDATA("Exposure",$K$16,"Aging Bucket","90+") -> 1929080135

Sheet Requirement (LGD)
D3: Exposure at Default Calculation (Part of Impairment Studio)
D6: A. For Trade Receivables: LGD = Percentage Loss After Default… It is LGD = 1 - Recovery Rate
D7: This tells us: "When a receivable defaults, how much do we actually lose?"
D10: B. Information Requirements for EAD
D11: Core Dataset — Historical Default Dataset
D13: Field | E13: Description | F13: Example | G13: Why Needed
D14: Customer ID | E14: Unique customer | F14: C014 | G14: Segmentation | O14: Steps to follow in general
D15: Invoice No | E15: Invoice reference | F15: INV1023 | G15: Traceability | O15: a. Upload LGD data in the data manager module. This data is called Trade Receivables Balances
D16: Original Amount | E16: Invoice value | F16: 5000000 | G16: Exposure | O16: b. In the LGD module, make sure you show the LGD Engine… both in table and in graph
D17: Amount Written Off | E17: Loss recognized | F17: 4200000 | G17: Default Loss | O17: Also in the :GD module, make sure you have the analysis
D18: Recovery Amount | E18: Amount recovered | F18: 600000 | G18: Recovery
D19: Write-off Date | E19: Default date | F19: 45301 | G19: Timing
D20: Segment | E20: Distributor/Retailer | F20: Distributor | G20: Analysis
D21: Region | E21: Lagos/Kano etc | F21: Lagos | G21: Analysis
D22: Product Type | E22: Flour/Rice | F22: Flour | G22: Analysis
D23: Days Past Due at Default | E23: DPD | F23: 210 | G23: Validation
D26: C. Derived Fields (To be calculated and show in the EAD module)
D29: Field | E29: Formula | F29: Purpose
D30: Recovery Rate | E30: recovery amt / written off amount | F30: LGD calc
D31: LGD per invoice | E31: 1 - recovery rate | F31: LGD calc
D32: Days Past Due
D34: D. With the above information your LGD is ready to go

Sheet LGD Engine
D3: LGD Calculation (Part of Impairment Studio)
D6: Historical Default Dataset
D7: Customer ID | E7: Invoice No | F7: Original Amount | G7: Amount Written Off | H7: Recovery Amount | I7: Write-off Date | J7: Segment | K7: Region | L7: Product Type | M7: Days Past Due at Default | N7: Aging Bucket | O7: Recovery Rate | P7: LGD per Invoice
D8: C230193 | E8: C230193_001 | F8: 155157121 | G8: 54304992 | H8: 23894197 | I8: 45627 | J8: Distributor | K8: Kano | L8: Product Type 2 | M8: =RANDBETWEEN(31,360) -> 85 | N8: =IF(M8<=0,"Current", IF(M8<=30,"1-30", IF(M8<=60,"31-60", IF(M8<=90,"61-90","90+")))) -> 61-90 | O8: =H8/G8 -> 0.44 | P8: =1-O8 -> 0.56
D9: C1360359 | E9: C1360359_001 | F9: 58647713 | G9: 55715327 | H9: 1114306.5 | I9: 45658 | J9: Distributor | K9: Port Harcourt | L9: Product Type 4 | M9: =RANDBETWEEN(31,360) -> 167 | N9: =IF(M9<=0,"Current", IF(M9<=30,"1-30", IF(M9<=60,"31-60", IF(M9<=90,"61-90","90+")))) -> 90+ | O9: =H9/G9 -> 0.02 | P9: =1-O9 -> 0.98
D10: C1463923 | E10: C1463923_001 | F10: 181787161 | G10: 1.2543314e+08 | H10: 43901599 | I10: 45689 | J10: Retailer | K10: Kano | L10: Product Type 2 | M10: =RANDBETWEEN(31,360) -> 346 | N10: =IF(M10<=0,"Current", IF(M10<=30,"1-30", IF(M10<=60,"31-60", IF(M10<=90,"61-90","90+")))) -> 90+ | O10: =H10/G10 -> 0.35 | P10: =1-O10 -> 0.65
D11: C2052553 | E11: C2052553_001 | F11: 36341554 | G11: 14900037 | H11: 1341003.3 | I11: 45717 | J11: Distributor | K11: Port Harcourt | L11: Product Type 4 | M11: =RANDBETWEEN(31,360) -> 192 | N11: =IF(M11<=0,"Current", IF(M11<=30,"1-30", IF(M11<=60,"31-60", IF(M11<=90,"61-90","90+")))) -> 90+ | O11: =H11/G11 -> 0.09 | P11: =1-O11 -> 0.91
D12: C1852993 | E12: C1852993_001 | F12: 62544476 | G12: 53162805 | H12: 21265122 | I12: 45748 | J12: Distributor | K12: Kano | L12: Product Type 4 | M12: =RANDBETWEEN(31,360) -> 294 | N12: =IF(M12<=0,"Current", IF(M12<=30,"1-30", IF(M12<=60,"31-60", IF(M12<=90,"61-90","90+")))) -> 90+ | O12: =H12/G12 -> 0.4 | P12: =1-O12 -> 0.6
D13: C578939 | E13: C578939_001 | F13: 133810345 | G13: 65567069 | H13: 12457743 | I13: 45778 | J13: Distributor | K13: Abuja | L13: Product Type 5 | M13: =RANDBETWEEN(31,360) -> 133 | N13: =IF(M13<=0,"Current", IF(M13<=30,"1-30", IF(M13<=60,"31-60", IF(M13<=90,"61-90","90+")))) -> 90+ | O13: =H13/G13 -> 0.19 | P13: =1-O13 -> 0.81
D14: C1685162 | E14: C1685162_001 | F14: 57293223 | G14: 50418036 | H14: 5041803.6 | I14: 45809 | J14: Distributor | K14: Kano | L14: Product Type 1 | M14: =RANDBETWEEN(31,360) -> 54 | N14: =IF(M14<=0,"Current", IF(M14<=30,"1-30", IF(M14<=60,"31-60", IF(M14<=90,"61-90","90+")))) -> 31-60 | O14: =H14/G14 -> 0.1 | P14: =1-O14 -> 0.9
D15: C1677221 | E15: C1677221_001 | F15: 113735516 | G15: 23884458 | H15: 477689.17 | I15: 45839 | J15: Distributor | K15: Kano | L15: Product Type 5 | M15: =RANDBETWEEN(31,360) -> 66 | N15: =IF(M15<=0,"Current", IF(M15<=30,"1-30", IF(M15<=60,"31-60", IF(M15<=90,"61-90","90+")))) -> 61-90 | O15: =H15/G15 -> 0.02 | P15: =1-O15 -> 0.98
D16: C818034 | E16: C818034_001 | F16: 73516834 | G16: 27201229 | H16: 16864762 | I16: 45870 | J16: Distributor | K16: Abuja | L16: Product Type 6 | M16: =RANDBETWEEN(31,360) -> 289 | N16: =IF(M16<=0,"Current", IF(M16<=30,"1-30", IF(M16<=60,"31-60", IF(M16<=90,"61-90","90+")))) -> 90+ | O16: =H16/G16 -> 0.62 | P16: =1-O16 -> 0.38
D17: C578517 | E17: C578517_001 | F17: 167972299 | G17: 50391690 | H17: 20156676 | I17: 45901 | J17: Distributor | K17: Ibadan | L17: Product Type 1 | M17: =RANDBETWEEN(31,360) -> 300 | N17: =IF(M17<=0,"Current", IF(M17<=30,"1-30", IF(M17<=60,"31-60", IF(M17<=90,"61-90","90+")))) -> 90+ | O17: =H17/G17 -> 0.4 | P17: =1-O17 -> 0.6
D18: C899761 | E18: C899761_001 | F18: 65534370 | G18: 25558404 | H18: 766752.13 | I18: 45931 | J18: Retailer | K18: Abuja | L18: Product Type 6 | M18: =RANDBETWEEN(31,360) -> 133 | N18: =IF(M18<=0,"Current", IF(M18<=30,"1-30", IF(M18<=60,"31-60", IF(M18<=90,"61-90","90+")))) -> 90+ | O18: =H18/G18 -> 0.03 | P18: =1-O18 -> 0.97
D19: C2256317 | E19: C2256317_001 | F19: 70918735 | G19: 41842054 | H19: 10878934 | I19: 45962 | J19: Retailer | K19: Abuja | L19: Product Type 2 | M19: =RANDBETWEEN(31,360) -> 132 | N19: =IF(M19<=0,"Current", IF(M19<=30,"1-30", IF(M19<=60,"31-60", IF(M19<=90,"61-90","90+")))) -> 90+ | O19: =H19/G19 -> 0.26 | P19: =1-O19 -> 0.74
... D439: C1946530 | E439: C1946530_001 | F439: 3991149 | G439: 2274954.9 | H439: 1000980.2 | I439: 58746 | J439: Distributor | K439: Abuja | L439: Product Type 6 | M439: =RANDBETWEEN(31,360) -> 157 | N439: =IF(M439<=0,"Current", IF(M439<=30,"1-30", IF(M439<=60,"31-60", IF(M439<=90,"61-90","90+")))) -> 90+ | O439: =H439/G439 -> 0.44 | P439: =1-O439 -> 0.56

Sheet LGD Analysis
C9: Analysis 1 — Overall LGD (Main Output)
C11: Analysis 2 — LGD by Aging Bucket (Advanced)
C13: Analysis 3 - Show LGD by segment, product
C15: Analysis 4 — Recovery Distribution | J15: Row Labels | K15: Exposure | L15: LGD
J16: 1-30 | K16: 249206509 | L16: =IFERROR(AVERAGEIF('LGD Engine'!$N$8:$N$439,'LGD Analysis'!J16,'LGD Engine'!$P$8:$P$439),0) -> 0
J17: 31-60 | K17: 1895773951 | L17: =IFERROR(AVERAGEIF('LGD Engine'!$N$8:$N$439,'LGD Analysis'!J17,'LGD Engine'!$P$8:$P$439),0) -> 0.65243243
C18: Graph 1 — Recovery vs Write-off Scatter | J18: 61-90 | K18: 249973198 | L18: =IFERROR(AVERAGEIF('LGD Engine'!$N$8:$N$439,'LGD Analysis'!J18,'LGD Engine'!$P$8:$P$439),0) -> 0.71961538
J19: 90+ | K19: 1929080135 | L19: =IFERROR(AVERAGEIF('LGD Engine'!$N$8:$N$439,'LGD Analysis'!J19,'LGD Engine'!$P$8:$P$439),0) -> 0.68034985
C20: Graph 2 — LGD Histogram | J20: Current | K20: 1910753232 | L20: =IFERROR(AVERAGEIF('LGD Engine'!$N$8:$N$439,'LGD Analysis'!J20,'LGD Engine'!$P$8:$P$439),0) -> 0
C23: Graph 3 — Average LGD Bar Chart | J23: Current | K23: 1910753232 | L23: =IFERROR(AVERAGEIF('LGD Engine'!$N$8:$N$439,'LGD Analysis'!J23,'LGD Engine'!$P$8:$P$439),0) -> 0
J24: 1-30 | K24: 249206509 | L24: =IFERROR(AVERAGEIF('LGD Engine'!$N$8:$N$439,'LGD Analysis'!J24,'LGD Engine'!$P$8:$P$439),0) -> 0
C25: Single bar: | J25: 31-60 | K25: 1895773951 | L25: =IFERROR(AVERAGEIF('LGD Engine'!$N$8:$N$439,'LGD Analysis'!J25,'LGD Engine'!$P$8:$P$439),0) -> 0.65243243
J26: 61-90 | K26: 249973198 | L26: =IFERROR(AVERAGEIF('LGD Engine'!$N$8:$N$439,'LGD Analysis'!J26,'LGD Engine'!$P$8:$P$439),0) -> 0.71961538
C27: LGD % | J27: 90+ | K27: 1929080135 | L27: =IFERROR(AVERAGEIF('LGD Engine'!$N$8:$N$439,'LGD Analysis'!J27,'LGD Engine'!$P$8:$P$439),0) -> 0.68034985
C29: Simple executive view.

Sheet Requirement (PD)
D3: Probability of Default Calculation (Part of Impairment Studio)
D6: PD here is Lifetime PD = Historical Defaults / Historical Exposure
D7: This tells us: "When a receivable defaults, how much do we actually lose?"
D10: B. Information Requirements for pd
D11: Dataset 1 — Historical Defaults (Numerator)
D12: Contains invoices that defaulted.
D14: Field | E14: Description | F14: Why Needed
D15: Customer ID | E15: Customer identifier | F15: Segmentation
D16: Invoice No | E16: Invoice reference | F16: Traceability | H16: Customer ID | I16: Invoice No | J16: Original Amount | K16: Amount Written Off | L16: Write-off Date | M16: Days Past Due at Default | N16: Aging Bucket | O16: Segment | P16: Region
D17: Original Amount | E17: Exposure | F17: Default value
D18: Amount Written Off | E18: Loss | F18: Default measurement
D19: Write-off Date | E19: Default date | F19: Timing
D20: Days Past Due at Default | E20: DPD | F20: Aging classification
D21: Aging Bucket | E21: Bucket at default | F21: PD calculation
D22: Segment | E22: Distributor/Retailer | F22: Analysis
D23: Region | E23: Geography | F23: Analysis
D26: Dataset 2 — Historical Exposure (Denominator)
D27: Dataset 2 — Historical Exposure (Denominator)
D29: Field | E29: Description | F29: Why Needed
D30: Reporting Date | E30: Month/Year | F30: Time series
D31: Current | E31: Exposure | F31: Denominator
D32: 1–30 | E32: Exposure | F32: Denominator
D33: 31–60 | E33: Exposure | F33: Denominator
D34: 61–90 | E34: Exposure | F34: Denominator
D35: 90+ | E35: Exposure | F35: Denominator

Sheet Historical Default
D3: Historical Default Dataset
D7: Invoice | E7: Amount Written Off | F7: Aging Bucket | G7: Segment | H7: Region | M7: Retailer | N7: Distributor | O7: Export
D8: INV10111 | E8: 83151804 | F8: 31-60 | G8: Distributor | H8: Kano | L8: {=_xlfn.UNIQUE(F8:F441)} -> 31-60 | M8: =SUMIFS($E$8:$E$441,$F$8:$F$441,$L8,$G$8:$G$441,M$7) -> 6.4598594e+08 | N8: =SUMIFS($E$8:$E$441,$F$8:$F$441,$L8,$G$8:$G$441,N$7) -> 8.122887e+08 | O8: =SUMIFS($E$8:$E$441,$F$8:$F$441,$L8,$G$8:$G$441,O$7) -> 2.0116335e+09
D9: INV1011198 | E9: 3877786.8 | F9: 61-90 | G9: Distributor | H9: Port Harcourt | L9: 61-90 | M9: =SUMIFS($E$8:$E$441,$F$8:$F$441,$L9,$G$8:$G$441,M$7) -> 2.4605883e+08 | N9: =SUMIFS($E$8:$E$441,$F$8:$F$441,$L9,$G$8:$G$441,N$7) -> 7.435227e+08 | O9: =SUMIFS($E$8:$E$441,$F$8:$F$441,$L9,$G$8:$G$441,O$7) -> 1.1110076e+09
D10: INV2012285 | E10: 1.5277757e+08 | F10: 90+ | G10: Retailer | H10: Kano | L10: 90+ | M10: =SUMIFS($E$8:$E$441,$F$8:$F$441,$L10,$G$8:$G$441,M$7) -> 8.1813355e+09 | N10: =SUMIFS($E$8:$E$441,$F$8:$F$441,$L10,$G$8:$G$441,N$7) -> 1.3738673e+10 | O10: =SUMIFS($E$8:$E$441,$F$8:$F$441,$L10,$G$8:$G$441,O$7) -> 2.5011302e+09
D11: INV3013372 | E11: 4666691.6 | F11: 31-60 | G11: Export | H11: Port Harcourt
D12: INV4014459 | E12: 74002624 | F12: 61-90 | G12: Distributor | H12: Kano
D13: INV5015546 | E13: 43352946 | F13: 90+ | G13: Distributor | H13: Abuja
D14: INV6016633 | E14: 17545477 | F14: 90+ | G14: Distributor | H14: Kano
D15: INV7017720 | E15: 1662358.3 | F15: 90+ | G15: Distributor | H15: Kano
D16: INV8018807 | E16: 58689371 | F16: 31-60 | G16: Distributor | H16: Abuja
D17: INV9019894 | E17: 70145232 | F17: 61-90 | G17: Distributor | H17: Ibadan
D18: INV10020981 | E18: 500000000 | F18: 31-60 | G18: Retailer | H18: Abuja
D19: INV11022068 | E19: 37858690 | F19: 90+ | G19: Retailer | H19: Abuja
D20: INV12023155 | E20: 8940952.4 | F20: 90+ | G20: Export | H20: Kaduna
D21: INV13024242 | E21: 77343363 | F21: 90+ | G21: Distributor | H21: Abuja
D22: INV14025329 | E22: 8940952.4 | F22: 90+ | G22: Retailer | H22: Port Harcourt
... D441: INV431478608 | E441: 3483411 | F441: 31-60 | G441: Export | H441: Abuja

Sheet Historical Exposure Dataset
D3: Historical Default Dataset
D6: Segment - Retail
D7: Year | E7: Current | F7: 1–30 | G7: 31–60 | H7: 61–90 | I7: 90+
D8: 2021 | E8: 45000000 | F8: 30000000 | G8: 20000000 | H8: 15000000 | I8: 1500000000 | M8: =E13 -> 300000000
D9: 2022 | E9: 50000000 | F9: 30000000 | G9: 20000000 | H9: 15000000 | I9: 4350000000 | M9: =F13 -> 184000000
D10: 2023 | E10: 60000000 | F10: 35000000 | G10: 25000000 | H10: 18000000 | I10: 1450000000 | M10: =G13 -> 138000000
D11: 2024 | E11: 70000000 | F11: 40000000 | G11: 30000000 | H11: 20000000 | I11: 500000000 | M11: =H13 -> 93000000
D12: 2025 | E12: 75000000 | F12: 49000000 | G12: 43000000 | H12: 25000000 | I12: 1500000000 | M12: =I13 -> 9300000000
E13: =SUM(E8:E12) -> 300000000 | F13: =SUM(F8:F12) -> 184000000 | G13: =SUM(G8:G12) -> 138000000 | H13: =SUM(H8:H12) -> 93000000 | I13: =SUM(I8:I12) -> 9300000000
D17: Segment - Distributor
D18: Year | E18: Current | F18: 1–30 | G18: 31–60 | H18: 61–90 | I18: 90+
D19: 2021 | E19: =E8*2.9 -> 130500000 | F19: =F8*2.9 -> 87000000 | G19: =G8*2.9 -> 58000000 | H19: 1000000 | I19: =I8*2.9 -> 4350000000 | M19: =E24 -> 870000000
D20: 2022 | E20: =E9*2.9 -> 145000000 | F20: =F9*2.9 -> 87000000 | G20: =G9*2.9 -> 58000000 | H20: =H9*2.9 -> 43500000 | I20: =I9*2.9 -> 12615000000 | M20: =F24 -> 533600000
D21: 2023 | E21: =E10*2.9 -> 174000000 | F21: =F10*2.9 -> 101500000 | G21: =G10*2.9 -> 72500000 | H21: =H10*2.9 -> 52200000 | I21: =I10*2.9 -> 4205000000 | M21: =G24 -> 400200000
D22: 2024 | E22: =E11*2.9 -> 203000000 | F22: =F11*2.9 -> 116000000 | G22: =G11*2.9 -> 87000000 | H22: =H11*2.9 -> 58000000 | I22: =I11*2.9 -> 1450000000 | M22: =H24 -> 227200000
D23: 2025 | E23: =E12*2.9 -> 217500000 | F23: =F12*2.9 -> 142100000 | G23: =G12*2.9 -> 124700000 | H23: =H12*2.9 -> 72500000 | I23: =I12*2.9 -> 4350000000 | M23: =I24 -> 26970000000
E24: =SUM(E19:E23) -> 870000000 | F24: =SUM(F19:F23) -> 533600000 | G24: =SUM(G19:G23) -> 400200000 | H24: =SUM(H19:H23) -> 227200000 | I24: =SUM(I19:I23) -> 26970000000
D28: Segment - Export
D29: Year | E29: Current | F29: 1–30 | G29: 31–60 | H29: 61–90 | I29: 90+
D30: 2021 | E30: =E19*2.9 -> 378450000 | F30: =F19*2.9 -> 252300000 | G30: 2000000 | H30: =H19*2.9 -> 2900000 | I30: 1000000000 | M30: =E35 -> 2523000000
D31: 2022 | E31: =E20*2.9 -> 420500000 | F31: =F20*2.9 -> 252300000 | G31: 2000000 | H31: =H20*2.9 -> 126150000 | I31: 1000000000 | M31: =F35 -> 1547440000
D32: 2023 | E32: =E21*2.9 -> 504600000 | F32: =F21*2.9 -> 294350000 | G32: 2000000 | H32: =H21*2.9 -> 151380000 | I32: 1000000000 | M32: =G35 -> 619930000
D33: 2024 | E33: =E22*2.9 -> 588700000 | F33: =F22*2.9 -> 336400000 | G33: =G22*2.9 -> 252300000 | H33: =H22*2.9 -> 168200000 | I33: 1000000000 | M33: =H35 -> 658880000
D34: 2025 | E34: =E23*2.9 -> 630750000 | F34: =F23*2.9 -> 412090000 | G34: =G23*2.9 -> 361630000 | H34: =H23*2.9 -> 210250000 | I34: 1000000000 | M34: =I35 -> 5000000000
E35: =SUM(E30:E34) -> 2523000000 | F35: =SUM(F30:F34) -> 1547440000 | G35: =SUM(G30:G34) -> 619930000 | H35: =SUM(H30:H34) -> 658880000 | I35: =SUM(I30:I34) -> 5000000000

Sheet PD Engine
D3: Historical Default Dataset (Pre-FLI) | J3: Final PDs
D6: Segment - Retailer | J6: Segment - Retailer
D7: Aging Bucket | E7: Exposure | F7: Default | G7: Lifetime PD | J7: Aging Bucket | K7: Baseline Scaler | L7: Upturn Scaler | M7: Downturn Scaler | N7: Baseline PD | O7: Upturn PD | P7: Downturn PD
D8: Current | E8: ='Historical Exposure Dataset'!M8 -> 300000000 | F8: 0 | G8: 0 | J8: Current | K8: 1 | L8: =K8-factor -> 0.99627977 | M8: =1+factor -> 1.0037202 | N8: =K8*G8 -> 0 | O8: =G8*L8 -> 0 | P8: =G8*M8 -> 0
D9: 1–30 | E9: ='Historical Exposure Dataset'!M9 -> 184000000 | F9: 0 | G9: 0 | J9: 1–30 | K9: 1 | L9: =K9-factor -> 0.99627977 | M9: =1+factor -> 1.0037202 | N9: =K9*G9 -> 0 | O9: =G9*L9 -> 0 | P9: =G9*M9 -> 0
D10: 31–60 | E10: ='Historical Exposure Dataset'!M10 -> 138000000 | F10: ='Historical Default'!M8 -> 6.4598594e+08 | G10: =E10/F10 -> 0.21362694 | J10: 31–60 | K10: 1 | L10: =K10-factor -> 0.99627977 | M10: =1+factor -> 1.0037202 | N10: =K10*G10 -> 0.21362694 | O10: =G10*L10 -> 0.2128322 | P10: =G10*M10 -> 0.21442168
D11: 61–90 | E11: ='Historical Exposure Dataset'!M11 -> 93000000 | F11: ='Historical Default'!M9 -> 2.4605883e+08 | G11: =E11/F11 -> 0.3779584 | J11: 61–90 | K11: 1 | L11: =K11-factor -> 0.99627977 | M11: =1+factor -> 1.0037202 | N11: =K11*G11 -> 0.3779584 | O11: =G11*L11 -> 0.37655231 | P11: =G11*M11 -> 0.37936449
D12: 90+ | E12: ='Historical Exposure Dataset'!M12 -> 9300000000 | F12: ='Historical Default'!M10 -> 8.1813355e+09 | G12: =MIN(1,E12/F12) -> 1 | J12: 90+ | K12: 1 | L12: =K12-factor -> 0.99627977 | M12: =1+factor -> 1.0037202 | N12: =K12*G12 -> 1 | O12: =G12*L12 -> 0.99627977 | P12: =G12*M12 -> 1.0037202
E13: =SUM(E8:E12) -> 10015000000
D17: Segment - Distributor | J17: Segment - Distributor
D18: Aging Bucket | E18: Exposure | F18: Default | G18: Lifetime PD | J18: Aging Bucket | K18: Baseline Scaler | L18: Upturn Scaler | M18: Downturn Scaler | N18: Baseline PD | O18: Upturn PD | P18: Downturn PD
D19: Current | E19: ='Historical Exposure Dataset'!M19 -> 870000000 | F19: 0 | G19: 0 | J19: Current | K19: 1 | L19: =K19-factor -> 0.99627977 | M19: =1+factor -> 1.0037202 | N19: =K19*G19 -> 0 | O19: =G19*L19 -> 0 | P19: =G19*M19 -> 0
D20: 1–30 | E20: ='Historical Exposure Dataset'!M20 -> 533600000 | F20: 0 | G20: 0 | J20: 1–30 | K20: 1 | L20: =K20-factor -> 0.99627977 | M20: =1+factor -> 1.0037202 | N20: =K20*G20 -> 0 | O20: =G20*L20 -> 0 | P20: =G20*M20 -> 0
D21: 31–60 | E21: ='Historical Exposure Dataset'!M21 -> 400200000 | F21: ='Historical Default'!N8 -> 8.122887e+08 | G21: =E21/F21 -> 0.49268198 | J21: 31–60 | K21: 1 | L21: =K21-factor -> 0.99627977 | M21: =1+factor -> 1.0037202 | N21: =K21*G21 -> 0.49268198 | O21: =G21*L21 -> 0.49084908 | P21: =G21*M21 -> 0.49451487
D22: 61–90 | E22: ='Historical Exposure Dataset'!M22 -> 227200000 | F22: ='Historical Default'!N9 -> 7.435227e+08 | G22: =E22/F22 -> 0.30557238 | J22: 61–90 | K22: 1 | L22: =K22-factor -> 0.99627977 | M22: =1+factor -> 1.0037202 | N22: =K22*G22 -> 0.30557238 | O22: =G22*L22 -> 0.30443558 | P22: =G22*M22 -> 0.30670918
D23: 90+ | E23: ='Historical Exposure Dataset'!M23 -> 26970000000 | F23: ='Historical Default'!N10 -> 1.3738673e+10 | G23: =MIN(1,E23/F23) -> 1 | J23: 90+ | K23: 1 | L23: =K23-factor -> 0.99627977 | M23: =1+factor -> 1.0037202 | N23: =K23*G23 -> 1 | O23: =G23*L23 -> 0.99627977 | P23: =G23*M23 -> 1.0037202
E24: =SUM(E19:E23) -> 29001000000 | F24: =SUM(F19:F23) -> 1.5294485e+10
D28: Segment - Export | J28: Segment - Export
D29: Aging Bucket | E29: Exposure | F29: Default | G29: Lifetime PD | J29: Aging Bucket | K29: Baseline Scaler | L29: Upturn Scaler | M29: Downturn Scaler | N29: Baseline PD | O29: Upturn PD | P29: Downturn PD
D30: Current | E30: ='Historical Exposure Dataset'!M30 -> 2523000000 | F30: 0 | G30: 0 | J30: Current | K30: 1 | L30: =K30-factor -> 0.99627977 | M30: =1+factor -> 1.0037202 | N30: =K30*G30 -> 0 | O30: =G30*L30 -> 0 | P30: =G30*M30 -> 0
D31: 1–30 | E31: ='Historical Exposure Dataset'!M31 -> 1547440000 | F31: 0 | G31: 0 | J31: 1–30 | K31: 1 | L31: =K31-factor -> 0.99627977 | M31: =1+factor -> 1.0037202 | N31: =K31*G31 -> 0 | O31: =G31*L31 -> 0 | P31: =G31*M31 -> 0
D32: 31–60 | E32: ='Historical Exposure Dataset'!M32 -> 619930000 | F32: ='Historical Default'!O8 -> 2.0116335e+09 | G32: =E32/F32 -> 0.30817244 | J32: 31–60 | K32: 1 | L32: =K32-factor -> 0.99627977 | M32: =1+factor -> 1.0037202 | N32: =K32*G32 -> 0.30817244 | O32: =G32*L32 -> 0.30702596 | P32: =G32*M32 -> 0.30931891
D33: 61–90 | E33: ='Historical Exposure Dataset'!M33 -> 658880000 | F33: ='Historical Default'!O9 -> 1.1110076e+09 | G33: =E33/F33 -> 0.59304724 | J33: 61–90 | K33: 1 | L33: =K33-factor -> 0.99627977 | M33: =1+factor -> 1.0037202 | N33: =K33*G33 -> 0.59304724 | O33: =G33*L33 -> 0.59084096 | P33: =G33*M33 -> 0.59525351
D34: 90+ | E34: ='Historical Exposure Dataset'!M34 -> 5000000000 | F34: ='Historical Default'!O10 -> 2.5011302e+09 | G34: =MIN(E34/F34,1) -> 1 | J34: 90+ | K34: 1 | L34: =K34-factor -> 0.99627977 | M34: =1+factor -> 1.0037202 | N34: =K34*G34 -> 1 | O34: =G34*L34 -> 0.99627977 | P34: =G34*M34 -> 1.0037202
E35: =SUM(E30:E34) -> 10349250000 | F35: =SUM(F30:F34) -> 5.6237713e+09 | G35: =SUM(G30:G34) -> 1.9012197

Sheet FLI
D3: Historical Macro-economic Data vs Industry Trade Receivables Bad Debt Ratio (60 months)
D7: Month | E7: Bad Debt Ratio (%) | F7: Inflation (%) | G7: FX Rate | H7: Interest Rate (%) | K7: Bad Debt Ratio (%) | L7: Inflation (%) | M7: FX Rate | N7: Interest Rate (%)
D8: 43831 | E8: 8.2e-05 | F8: 0.11 | G8: 360 | H8: 0.12 | I8: =E8/100 -> 8.2e-07 | K8: =STANDARDIZE(E8,AVERAGE($E$8:$E$67),_xlfn.STDEV.S($E$8:$E$67)) -> -2.4029633 | L8: =STANDARDIZE(F8,AVERAGE($F$8:$F$67),_xlfn.STDEV.S($F$8:$F$67)) -> -1.7497928 | M8: =STANDARDIZE(G8,AVERAGE($G$8:$G$67),_xlfn.STDEV.S($G$8:$G$67)) -> -0.85428945 | N8: =STANDARDIZE(H8,AVERAGE($H$8:$H$67),_xlfn.STDEV.S($H$8:$H$67)) -> -1.3078735 | Q8: SUMMARY OUTPUT
D9: 43862 | E9: 0.0085 | F9: 0.112 | G9: 362 | H9: 0.121 | I9: =E9/100 -> 8.5e-05 | K9: =STANDARDIZE(E9,AVERAGE($E$8:$E$67),_xlfn.STDEV.S($E$8:$E$67)) -> -1.2933172 | L9: =STANDARDIZE(F9,AVERAGE($F$8:$F$67),_xlfn.STDEV.S($F$8:$F$67)) -> -1.710684 | M9: =STANDARDIZE(G9,AVERAGE($G$8:$G$67),_xlfn.STDEV.S($G$8:$G$67)) -> -0.85030705 | N9: =STANDARDIZE(H9,AVERAGE($H$8:$H$67),_xlfn.STDEV.S($H$8:$H$67)) -> -1.2881618
D10: 43891 | E10: 0.0088 | F10: 0.115 | G10: 365 | H10: 0.123 | I10: =E10/100 -> 8.8e-05 | K10: =STANDARDIZE(E10,AVERAGE($E$8:$E$67),_xlfn.STDEV.S($E$8:$E$67)) -> -1.2537718 | L10: =STANDARDIZE(F10,AVERAGE($F$8:$F$67),_xlfn.STDEV.S($F$8:$F$67)) -> -1.6520208 | M10: =STANDARDIZE(G10,AVERAGE($G$8:$G$67),_xlfn.STDEV.S($G$8:$G$67)) -> -0.84433347 | N10: =STANDARDIZE(H10,AVERAGE($H$8:$H$67),_xlfn.STDEV.S($H$8:$H$67)) -> -1.2487383 | Q10: Regression Statistics
D11: 43922 | E11: 0.0092 | F11: 0.12 | G11: 368 | H11: 0.126 | I11: =E11/100 -> 9.2e-05 | K11: =STANDARDIZE(E11,AVERAGE($E$8:$E$67),_xlfn.STDEV.S($E$8:$E$67)) -> -1.2010445 | L11: =STANDARDIZE(F11,AVERAGE($F$8:$F$67),_xlfn.STDEV.S($F$8:$F$67)) -> -1.5542488 | M11: =STANDARDIZE(G11,AVERAGE($G$8:$G$67),_xlfn.STDEV.S($G$8:$G$67)) -> -0.83835988 | N11: =STANDARDIZE(H11,AVERAGE($H$8:$H$67),_xlfn.STDEV.S($H$8:$H$67)) -> -1.1896031 | Q11: Multiple R | R11: 0.99864103
D12: 43952 | E12: 0.0096 | F12: 0.125 | G12: 372 | H12: 0.129 | I12: =E12/100 -> 9.6e-05 | K12: =STANDARDIZE(E12,AVERAGE($E$8:$E$67),_xlfn.STDEV.S($E$8:$E$67)) -> -1.1483172 | L12: =STANDARDIZE(F12,AVERAGE($F$8:$F$67),_xlfn.STDEV.S($F$8:$F$67)) -> -1.4564768 | M12: =STANDARDIZE(G12,AVERAGE($G$8:$G$67),_xlfn.STDEV.S($G$8:$G$67)) -> -0.83039509 | N12: =STANDARDIZE(H12,AVERAGE($H$8:$H$67),_xlfn.STDEV.S($H$8:$H$67)) -> -1.1304679 | Q12: R Square | R12: 0.99728391
D13: 43983 | E13: 0.0102 | F13: 0.13 | G13: 380 | H13: 0.132 | I13: =E13/100 -> 0.000102 | K13: =STANDARDIZE(E13,AVERAGE($E$8:$E$67),_xlfn.STDEV.S($E$8:$E$67)) -> -1.0692262 | L13: =STANDARDIZE(F13,AVERAGE($F$8:$F$67),_xlfn.STDEV.S($F$8:$F$67)) -> -1.3587048 | M13: =STANDARDIZE(G13,AVERAGE($G$8:$G$67),_xlfn.STDEV.S($G$8:$G$67)) -> -0.81446553 | N13: =STANDARDIZE(H13,AVERAGE($H$8:$H$67),_xlfn.STDEV.S($H$8:$H$67)) -> -1.0713327 | Q13: Adjusted R Square | R13: 0.99713841
D14: 44013 | E14: 0.0108 | F14: 0.135 | G14: 385 | H14: 0.135 | I14: =E14/100 -> 0.000108 | K14: =STANDARDIZE(E14,AVERAGE($E$8:$E$67),_xlfn.STDEV.S($E$8:$E$67)) -> -0.99013525 | L14: =STANDARDIZE(F14,AVERAGE($F$8:$F$67),_xlfn.STDEV.S($F$8:$F$67)) -> -1.2609328 | M14: =STANDARDIZE(G14,AVERAGE($G$8:$G$67),_xlfn.STDEV.S($G$8:$G$67)) -> -0.80450955 | N14: =STANDARDIZE(H14,AVERAGE($H$8:$H$67),_xlfn.STDEV.S($H$8:$H$67)) -> -1.0121975 | Q14: Standard Error | R14: 0.05349383
D15: 44044 | E15: 0.0112 | F15: 0.14 | G15: 390 | H15: 0.137 | I15: =E15/100 -> 0.000112 | K15: =STANDARDIZE(E15,AVERAGE($E$8:$E$67),_xlfn.STDEV.S($E$8:$E$67)) -> -0.93740795 | L15: =STANDARDIZE(F15,AVERAGE($F$8:$F$67),_xlfn.STDEV.S($F$8:$F$67)) -> -1.1631608 | M15: =STANDARDIZE(G15,AVERAGE($G$8:$G$67),_xlfn.STDEV.S($G$8:$G$67)) -> -0.79455357 | N15: =STANDARDIZE(H15,AVERAGE($H$8:$H$67),_xlfn.STDEV.S($H$8:$H$67)) -> -0.97277407 | Q15: Observations | R15: 60
D16: 44075 | E16: 0.0118 | F16: 0.145 | G16: 395 | H16: 0.14 | I16: =E16/100 -> 0.000118 | K16: =STANDARDIZE(E16,AVERAGE($E$8:$E$67),_xlfn.STDEV.S($E$8:$E$67)) -> -0.858317 | L16: =STANDARDIZE(F16,AVERAGE($F$8:$F$67),_xlfn.STDEV.S($F$8:$F$67)) -> -1.0653888 | M16: =STANDARDIZE(G16,AVERAGE($G$8:$G$67),_xlfn.STDEV.S($G$8:$G$67)) -> -0.78459759 | N16: =STANDARDIZE(H16,AVERAGE($H$8:$H$67),_xlfn.STDEV.S($H$8:$H$67)) -> -0.91363887
D17: 44105 | E17: 0.0125 | F17: 0.15 | G17: 400 | H17: 0.143 | I17: =E17/100 -> 0.000125 | K17: =STANDARDIZE(E17,AVERAGE($E$8:$E$67),_xlfn.STDEV.S($E$8:$E$67)) -> -0.76604422 | L17: =STANDARDIZE(F17,AVERAGE($F$8:$F$67),_xlfn.STDEV.S($F$8:$F$67)) -> -0.96761685 | M17: =STANDARDIZE(G17,AVERAGE($G$8:$G$67),_xlfn.STDEV.S($G$8:$G$67)) -> -0.77464161 | N17: =STANDARDIZE(H17,AVERAGE($H$8:$H$67),_xlfn.STDEV.S($H$8:$H$67)) -> -0.85450367 | Q17: ANOVA
D18: 44136 | E18: 0.0128 | F18: 0.155 | G18: 405 | H18: 0.146 | I18: =E18/100 -> 0.000128 | K18: =STANDARDIZE(E18,AVERAGE($E$8:$E$67),_xlfn.STDEV.S($E$8:$E$67)) -> -0.72649874 | L18: =STANDARDIZE(F18,AVERAGE($F$8:$F$67),_xlfn.STDEV.S($F$8:$F$67)) -> -0.86984485 | M18: =STANDARDIZE(G18,AVERAGE($G$8:$G$67),_xlfn.STDEV.S($G$8:$G$67)) -> -0.76468563 | N18: =STANDARDIZE(H18,AVERAGE($H$8:$H$67),_xlfn.STDEV.S($H$8:$H$67)) -> -0.79536846 | R18: df | S18: SS | T18: MS | U18: F | V18: Significance F
D19: 44166 | E19: 0.0132 | F19: 0.16 | G19: 410 | H19: 0.15 | I19: =E19/100 -> 0.000132 | K19: =STANDARDIZE(E19,AVERAGE($E$8:$E$67),_xlfn.STDEV.S($E$8:$E$67)) -> -0.67377144 | L19: =STANDARDIZE(F19,AVERAGE($F$8:$F$67),_xlfn.STDEV.S($F$8:$F$67)) -> -0.77207286 | M19: =STANDARDIZE(G19,AVERAGE($G$8:$G$67),_xlfn.STDEV.S($G$8:$G$67)) -> -0.75472965 | N19: =STANDARDIZE(H19,AVERAGE($H$8:$H$67),_xlfn.STDEV.S($H$8:$H$67)) -> -0.71652153 | Q19: Regression | R19: 3 | S19: 58.839751 | T19: 19.61325 | U19: 6853.9698 | V19: 8.5433299e-72
D20: 44197 | E20: 0.013 | F20: 0.162 | G20: 415 | H20: 0.148 | I20: =E20/100 -> 0.00013 | K20: =STANDARDIZE(E20,AVERAGE($E$8:$E$67),_xlfn.STDEV.S($E$8:$E$67)) -> -0.70013509 | L20: =STANDARDIZE(F20,AVERAGE($F$8:$F$67),_xlfn.STDEV.S($F$8:$F$67)) -> -0.73296406 | M20: =STANDARDIZE(G20,AVERAGE($G$8:$G$67),_xlfn.STDEV.S($G$8:$G$67)) -> -0.74477367 | N20: =STANDARDIZE(H20,AVERAGE($H$8:$H$67),_xlfn.STDEV.S($H$8:$H$67)) -> -0.755945 | Q20: Residual | R20: 56 | S20: 0.16024903 | T20: 0.0028615898
D21: 44228 | E21: 0.0128 | F21: 0.16 | G21: 420 | H21: 0.145 | I21: =E21/100 -> 0.000128 | K21: =STANDARDIZE(E21,AVERAGE($E$8:$E$67),_xlfn.STDEV.S($E$8:$E$67)) -> -0.72649874 | L21: =STANDARDIZE(F21,AVERAGE($F$8:$F$67),_xlfn.STDEV.S($F$8:$F$67)) -> -0.77207286 | M21: =STANDARDIZE(G21,AVERAGE($G$8:$G$67),_xlfn.STDEV.S($G$8:$G$67)) -> -0.73481769 | N21: =STANDARDIZE(H21,AVERAGE($H$8:$H$67),_xlfn.STDEV.S($H$8:$H$67)) -> -0.8150802 | Q21: Total | R21: 59 | S21: 59
D22: 44256 | E22: 0.0125 | F22: 0.158 | G22: 422 | H22: 0.142 | I22: =E22/100 -> 0.000125 | K22: =STANDARDIZE(E22,AVERAGE($E$8:$E$67),_xlfn.STDEV.S($E$8:$E$67)) -> -0.76604422 | L22: =STANDARDIZE(F22,AVERAGE($F$8:$F$67),_xlfn.STDEV.S($F$8:$F$67)) -> -0.81118165 | M22: =STANDARDIZE(G22,AVERAGE($G$8:$G$67),_xlfn.STDEV.S($G$8:$G$67)) -> -0.7308353 | N22: =STANDARDIZE(H22,AVERAGE($H$8:$H$67),_xlfn.STDEV.S($H$8:$H$67)) -> -0.8742154
D23: 44287 | E23: 0.0122 | F23: 0.155 | G23: 425 | H23: 0.14 | I23: =E23/100 -> 0.000122 | K23: =STANDARDIZE(E23,AVERAGE($E$8:$E$67),_xlfn.STDEV.S($E$8:$E$67)) -> -0.80558969 | L23: =STANDARDIZE(F23,AVERAGE($F$8:$F$67),_xlfn.STDEV.S($F$8:$F$67)) -> -0.86984485 | M23: =STANDARDIZE(G23,AVERAGE($G$8:$G$67),_xlfn.STDEV.S($G$8:$G$67)) -> -0.72486171 | N23: =STANDARDIZE(H23,AVERAGE($H$8:$H$67),_xlfn.STDEV.S($H$8:$H$67)) -> -0.91363887 | R23: Coefficients | S23: Standard Error | T23: t Stat | U23: P-value | V23: Lower 95% | W23: Upper 95% | X23: Lower 95.0% | Y23: Upper 95.0%
D24: 44317 | E24: 0.0118 | F24: 0.152 | G24: 428 | H24: 0.138 | I24: =E24/100 -> 0.000118 | K24: =STANDARDIZE(E24,AVERAGE($E$8:$E$67),_xlfn.STDEV.S($E$8:$E$67)) -> -0.858317 | L24: =STANDARDIZE(F24,AVERAGE($F$8:$F$67),_xlfn.STDEV.S($F$8:$F$67)) -> -0.92850805 | M24: =STANDARDIZE(G24,AVERAGE($G$8:$G$67),_xlfn.STDEV.S($G$8:$G$67)) -> -0.71888812 | N24: =STANDARDIZE(H24,AVERAGE($H$8:$H$67),_xlfn.STDEV.S($H$8:$H$67)) -> -0.95306234 | Q24: Intercept | R24: 1.336947e-16 | S24: 0.0069060237 | T24: 1.9359143e-14 | U24: 1 | V24: -0.013834428 | W24: 0.013834428 | X24: -0.013834428 | Y24: 0.013834428
D25: 44348 | E25: 0.0115 | F25: 0.15 | G25: 430 | H25: 0.136 | I25: =E25/100 -> 0.000115 | K25: =STANDARDIZE(E25,AVERAGE($E$8:$E$67),_xlfn.STDEV.S($E$8:$E$67)) -> -0.89786247 | L25: =STANDARDIZE(F25,AVERAGE($F$8:$F$67),_xlfn.STDEV.S($F$8:$F$67)) -> -0.96761685 | M25: =STANDARDIZE(G25,AVERAGE($G$8:$G$67),_xlfn.STDEV.S($G$8:$G$67)) -> -0.71490573 | N25: =STANDARDIZE(H25,AVERAGE($H$8:$H$67),_xlfn.STDEV.S($H$8:$H$67)) -> -0.9924858 | Q25: Inflation (%) | R25: 0.088047415 | S25: 0.024427553 | T25: 3.6044304 | U25: 0.00066604959 | V25: 0.039113146 | W25: 0.13698168 | X25: 0.039113146 | Y25: 0.13698168
D26: 44378 | E26: 0.0112 | F26: 0.152 | G26: 432 | H26: 0.135 | I26: =E26/100 -> 0.000112 | K26: =STANDARDIZE(E26,AVERAGE($E$8:$E$67),_xlfn.STDEV.S($E$8:$E$67)) -> -0.93740795 | L26: =STANDARDIZE(F26,AVERAGE($F$8:$F$67),_xlfn.STDEV.S($F$8:$F$67)) -> -0.92850805 | M26: =STANDARDIZE(G26,AVERAGE($G$8:$G$67),_xlfn.STDEV.S($G$8:$G$67)) -> -0.71092334 | N26: =STANDARDIZE(H26,AVERAGE($H$8:$H$67),_xlfn.STDEV.S($H$8:$H$67)) -> -1.0121975 | Q26: FX Rate | R26: 0.26907077 | S26: 0.019853137 | T26: 13.553061 | U26: 2.5161352e-19 | V26: 0.22930016 | W26: 0.30884139 | X26: 0.22930016 | Y26: 0.30884139
D27: 44409 | E27: 0.0114 | F27: 0.155 | G27: 435 | H27: 0.136 | I27: =E27/100 -> 0.000114 | K27: =STANDARDIZE(E27,AVERAGE($E$8:$E$67),_xlfn.STDEV.S($E$8:$E$67)) -> -0.9110443 | L27: =STANDARDIZE(F27,AVERAGE($F$8:$F$67),_xlfn.STDEV.S($F$8:$F$67)) -> -0.86984485 | M27: =STANDARDIZE(G27,AVERAGE($G$8:$G$67),_xlfn.STDEV.S($G$8:$G$67)) -> -0.70494975 | N27: =STANDARDIZE(H27,AVERAGE($H$8:$H$67),_xlfn.STDEV.S($H$8:$H$67)) -> -0.9924858 | Q27: Interest Rate (%) | R27: 0.68201884 | S27: 0.037168117 | T27: 18.349567 | U27: 2.3628387e-25 | V27: 0.60756215 | W27: 0.75647552 | X27: 0.60756215 | Y27: 0.75647552
D28: 44440 | E28: 0.0118 | F28: 0.16 | G28: 438 | H28: 0.138 | I28: =E28/100 -> 0.000118 | K28: =STANDARDIZE(E28,AVERAGE($E$8:$E$67),_xlfn.STDEV.S($E$8:$E$67)) -> -0.858317 | L28: =STANDARDIZE(F28,AVERAGE($F$8:$F$67),_xlfn.STDEV.S($F$8:$F$67)) -> -0.77207286 | M28: =STANDARDIZE(G28,AVERAGE($G$8:$G$67),_xlfn.STDEV.S($G$8:$G$67)) -> -0.69897616 | N28: =STANDARDIZE(H28,AVERAGE($H$8:$H$67),_xlfn.STDEV.S($H$8:$H$67)) -> -0.95306234
D29: 44470 | E29: 0.0122 | F29: 0.165 | G29: 440 | H29: 0.14 | I29: =E29/100 -> 0.000122 | K29: =STANDARDIZE(E29,AVERAGE($E$8:$E$67),_xlfn.STDEV.S($E$8:$E$67)) -> -0.80558969 | L29: =STANDARDIZE(F29,AVERAGE($F$8:$F$67),_xlfn.STDEV.S($F$8:$F$67)) -> -0.67430086 | M29: =STANDARDIZE(G29,AVERAGE($G$8:$G$67),_xlfn.STDEV.S($G$8:$G$67)) -> -0.69499377 | N29: =STANDARDIZE(H29,AVERAGE($H$8:$H$67),_xlfn.STDEV.S($H$8:$H$67)) -> -0.91363887
D30: 44501 | E30: 0.0126 | F30: 0.17 | G30: 445 | H30: 0.142 | I30: =E30/100 -> 0.000126 | K30: =STANDARDIZE(E30,AVERAGE($E$8:$E$67),_xlfn.STDEV.S($E$8:$E$67)) -> -0.75286239 | L30: =STANDARDIZE(F30,AVERAGE($F$8:$F$67),_xlfn.STDEV.S($F$8:$F$67)) -> -0.57652887 | M30: =STANDARDIZE(G30,AVERAGE($G$8:$G$67),_xlfn.STDEV.S($G$8:$G$67)) -> -0.68503779 | N30: =STANDARDIZE(H30,AVERAGE($H$8:$H$67),_xlfn.STDEV.S($H$8:$H$67)) -> -0.8742154
D31: 44531 | E31: 0.013 | F31: 0.175 | G31: 450 | H31: 0.145 | I31: =E31/100 -> 0.00013 | K31: =STANDARDIZE(E31,AVERAGE($E$8:$E$67),_xlfn.STDEV.S($E$8:$E$67)) -> -0.70013509 | L31: =STANDARDIZE(F31,AVERAGE($F$8:$F$67),_xlfn.STDEV.S($F$8:$F$67)) -> -0.47875687 | M31: =STANDARDIZE(G31,AVERAGE($G$8:$G$67),_xlfn.STDEV.S($G$8:$G$67)) -> -0.67508181 | N31: =STANDARDIZE(H31,AVERAGE($H$8:$H$67),_xlfn.STDEV.S($H$8:$H$67)) -> -0.8150802
D32: 44562 | E32: 0.0135 | F32: 0.18 | G32: 455 | H32: 0.15 | I32: =E32/100 -> 0.000135 | K32: =STANDARDIZE(E32,AVERAGE($E$8:$E$67),_xlfn.STDEV.S($E$8:$E$67)) -> -0.63422596 | L32: =STANDARDIZE(F32,AVERAGE($F$8:$F$67),_xlfn.STDEV.S($F$8:$F$67)) -> -0.38098487 | M32: =STANDARDIZE(G32,AVERAGE($G$8:$G$67),_xlfn.STDEV.S($G$8:$G$67)) -> -0.66512583 | N32: =STANDARDIZE(H32,AVERAGE($H$8:$H$67),_xlfn.STDEV.S($H$8:$H$67)) -> -0.71652153
D33: 44593 | E33: 0.014 | F33: 0.185 | G33: 460 | H33: 0.153 | I33: =E33/100 -> 0.00014 | K33: =STANDARDIZE(E33,AVERAGE($E$8:$E$67),_xlfn.STDEV.S($E$8:$E$67)) -> -0.56831683 | L33: =STANDARDIZE(F33,AVERAGE($F$8:$F$67),_xlfn.STDEV.S($F$8:$F$67)) -> -0.28321288 | M33: =STANDARDIZE(G33,AVERAGE($G$8:$G$67),_xlfn.STDEV.S($G$8:$G$67)) -> -0.65516985 | N33: =STANDARDIZE(H33,AVERAGE($H$8:$H$67),_xlfn.STDEV.S($H$8:$H$67)) -> -0.65738633
D34: 44621 | E34: 0.0145 | F34: 0.19 | G34: 465 | H34: 0.157 | I34: =E34/100 -> 0.000145 | K34: =STANDARDIZE(E34,AVERAGE($E$8:$E$67),_xlfn.STDEV.S($E$8:$E$67)) -> -0.50240771 | L34: =STANDARDIZE(F34,AVERAGE($F$8:$F$67),_xlfn.STDEV.S($F$8:$F$67)) -> -0.18544088 | M34: =STANDARDIZE(G34,AVERAGE($G$8:$G$67),_xlfn.STDEV.S($G$8:$G$67)) -> -0.64521387 | N34: =STANDARDIZE(H34,AVERAGE($H$8:$H$67),_xlfn.STDEV.S($H$8:$H$67)) -> -0.57853939
D35: 44652 | E35: 0.015 | F35: 0.195 | G35: 470 | H35: 0.16 | I35: =E35/100 -> 0.00015 | K35: =STANDARDIZE(E35,AVERAGE($E$8:$E$67),_xlfn.STDEV.S($E$8:$E$67)) -> -0.43649858 | L35: =STANDARDIZE(F35,AVERAGE($F$8:$F$67),_xlfn.STDEV.S($F$8:$F$67)) -> -0.087668889 | M35: =STANDARDIZE(G35,AVERAGE($G$8:$G$67),_xlfn.STDEV.S($G$8:$G$67)) -> -0.63525789 | N35: =STANDARDIZE(H35,AVERAGE($H$8:$H$67),_xlfn.STDEV.S($H$8:$H$67)) -> -0.51940419
D36: 44682 | E36: 0.0155 | F36: 0.2 | G36: 480 | H36: 0.165 | I36: =E36/100 -> 0.000155 | K36: =STANDARDIZE(E36,AVERAGE($E$8:$E$67),_xlfn.STDEV.S($E$8:$E$67)) -> -0.37058945 | L36: =STANDARDIZE(F36,AVERAGE($F$8:$F$67),_xlfn.STDEV.S($F$8:$F$67)) -> 0.010103106 | M36: =STANDARDIZE(G36,AVERAGE($G$8:$G$67),_xlfn.STDEV.S($G$8:$G$67)) -> -0.61534593 | N36: =STANDARDIZE(H36,AVERAGE($H$8:$H$67),_xlfn.STDEV.S($H$8:$H$67)) -> -0.42084552
D37: 44713 | E37: 0.016 | F37: 0.205 | G37: 490 | H37: 0.17 | I37: =E37/100 -> 0.00016 | K37: =STANDARDIZE(E37,AVERAGE($E$8:$E$67),_xlfn.STDEV.S($E$8:$E$67)) -> -0.30468032 | L37: =STANDARDIZE(F37,AVERAGE($F$8:$F$67),_xlfn.STDEV.S($F$8:$F$67)) -> 0.1078751 | M37: =STANDARDIZE(G37,AVERAGE($G$8:$G$67),_xlfn.STDEV.S($G$8:$G$67)) -> -0.59543397 | N37: =STANDARDIZE(H37,AVERAGE($H$8:$H$67),_xlfn.STDEV.S($H$8:$H$67)) -> -0.32228685
D38: 44743 | E38: 0.0165 | F38: 0.21 | G38: 500 | H38: 0.175 | I38: =E38/100 -> 0.000165 | K38: =STANDARDIZE(E38,AVERAGE($E$8:$E$67),_xlfn.STDEV.S($E$8:$E$67)) -> -0.23877119 | L38: =STANDARDIZE(F38,AVERAGE($F$8:$F$67),_xlfn.STDEV.S($F$8:$F$67)) -> 0.2056471 | M38: =STANDARDIZE(G38,AVERAGE($G$8:$G$67),_xlfn.STDEV.S($G$8:$G$67)) -> -0.57552201 | N38: =STANDARDIZE(H38,AVERAGE($H$8:$H$67),_xlfn.STDEV.S($H$8:$H$67)) -> -0.22372818
D39: 44774 | E39: 0.017 | F39: 0.215 | G39: 510 | H39: 0.18 | I39: =E39/100 -> 0.00017 | K39: =STANDARDIZE(E39,AVERAGE($E$8:$E$67),_xlfn.STDEV.S($E$8:$E$67)) -> -0.17286207 | L39: =STANDARDIZE(F39,AVERAGE($F$8:$F$67),_xlfn.STDEV.S($F$8:$F$67)) -> 0.30341909 | M39: =STANDARDIZE(G39,AVERAGE($G$8:$G$67),_xlfn.STDEV.S($G$8:$G$67)) -> -0.55561005 | N39: =STANDARDIZE(H39,AVERAGE($H$8:$H$67),_xlfn.STDEV.S($H$8:$H$67)) -> -0.12516951
... D67: 45627 | E67: 0.025 | F67: 0.212 | G67: 1780 | H67: 0.215 | I67: =E67/100 -> 0.00025 | K67: =STANDARDIZE(E67,AVERAGE($E$8:$E$67),_xlfn.STDEV.S($E$8:$E$67)) -> 0.88168398 | L67: =STANDARDIZE(F67,AVERAGE($F$8:$F$67),_xlfn.STDEV.S($F$8:$F$67)) -> 0.24475589 | M67: =STANDARDIZE(G67,AVERAGE($G$8:$G$67),_xlfn.STDEV.S($G$8:$G$67)) -> 1.9732088 | N67: =STANDARDIZE(H67,AVERAGE($H$8:$H$67),_xlfn.STDEV.S($H$8:$H$67)) -> 0.56474118
D68: =EOMONTH(D67,1) -> 45688 | E68: =(intercept+beta1*F68+beta2*G68+beta3*H68)/10000 -> 0.049253666 | F68: =_xlfn.FORECAST.ETS(D68,F8:F67,D8:D67) -> 0.21685221 | G68: =_xlfn.FORECAST.ETS(D68,G8:G67,D8:D67) -> 1829.7737 | H68: =_xlfn.FORECAST.ETS(D68,H8:H67,D8:D67) -> 0.26236951
D69: =EOMONTH(D68,1) -> 45716 | E69: =(intercept+beta1*F69+beta2*G69+beta3*H69)/10000 -> 0.049859733 | F69: =_xlfn.FORECAST.ETS(D69,F9:F68,D9:D68) -> 0.21888478 | G69: =_xlfn.FORECAST.ETS(D69,G9:G68,D9:D68) -> 1852.2915 | H69: =_xlfn.FORECAST.ETS(D69,H9:H68,D9:D68) -> 0.26471604
D70: =EOMONTH(D69,1) -> 45747 | E70: =(intercept+beta1*F70+beta2*G70+beta3*H70)/10000 -> 0.050544184 | F70: =_xlfn.FORECAST.ETS(D70,F10:F69,D10:D69) -> 0.22122229 | G70: =_xlfn.FORECAST.ETS(D70,G10:G69,D10:D69) -> 1877.7211 | H70: =_xlfn.FORECAST.ETS(D70,H10:H69,D10:D69) -> 0.26757295
D71: =EOMONTH(D70,1) -> 45777 | E71: =(intercept+beta1*F71+beta2*G71+beta3*H71)/10000 -> 0.051191615 | F71: =_xlfn.FORECAST.ETS(D71,F11:F70,D11:D70) -> 0.22317245 | G71: =_xlfn.FORECAST.ETS(D71,G11:G70,D11:D70) -> 1901.7758 | H71: =_xlfn.FORECAST.ETS(D71,H11:H70,D11:D70) -> 0.27010063
D72: =EOMONTH(D71,1) -> 45808 | E72: =(intercept+beta1*F72+beta2*G72+beta3*H72)/10000 -> 0.051869778 | F72: =_xlfn.FORECAST.ETS(D72,F12:F71,D12:D71) -> 0.22513862 | G72: =_xlfn.FORECAST.ETS(D72,G12:G71,D12:D71) -> 1926.9722 | H72: =_xlfn.FORECAST.ETS(D72,H12:H71,D12:D71) -> 0.27280549
...

Sheet Sheet13
C2: ECL
C3: Segment - Retailer
C4: Aging Bucket | D4: Baseline PD | E4: Upturn PD | F4: Downturn PD | G4: LGD | H4: EAD | J4: ECL Base | K4: Ecl Up | L4: Ecl Down
C5: Current | D5: ='PD Engine'!N8 -> 0 | E5: ='PD Engine'!O8 -> 0 | F5: ='PD Engine'!P8 -> 0 | G5: ='LGD Analysis'!L23 -> 0 | H5: ='EAD Analysis'!L30 -> 1910753232 | J5: =H5*G5*D5 -> 0 | K5: =H5*G5*E5 -> 0 | L5: =H5*G5*F5 -> 0
C6: 1–30 | D6: ='PD Engine'!N9 -> 0 | E6: ='PD Engine'!O9 -> 0 | F6: ='PD Engine'!P9 -> 0 | G6: ='LGD Analysis'!L24 -> 0 | H6: ='EAD Analysis'!L31 -> 249206509 | J6: =H6*G6*D6 -> 0 | K6: =H6*G6*E6 -> 0 | L6: =H6*G6*F6 -> 0
C7: 31–60 | D7: ='PD Engine'!N10 -> 0.21362694 | E7: ='PD Engine'!O10 -> 0.2128322 | F7: ='PD Engine'!P10 -> 0.21442168 | G7: ='LGD Analysis'!L25 -> 0.65243243 | H7: ='EAD Analysis'!L32 -> 1895773951 | J7: =H7*G7*D7 -> 2.6422756e+08 | K7: =H7*G7*E7 -> 2.6324457e+08 | L7: =H7*G7*F7 -> 2.6521055e+08 | M7: =AVERAGE(J7:L7) -> 2.6422756e+08
C8: 61–90 | D8: ='PD Engine'!N11 -> 0.3779584 | E8: ='PD Engine'!O11 -> 0.37655231 | F8: ='PD Engine'!P11 -> 0.37936449 | G8: ='LGD Analysis'!L26 -> 0.71961538 | H8: ='EAD Analysis'!L33 -> 249973198 | J8: =H8*G8*D8 -> 67988880 | K8: =H8*G8*E8 -> 67735945 | L8: =H8*G8*F8 -> 68241814 | M8: =AVERAGE(J8:L8) -> 67988880
C9: 90+ | D9: ='PD Engine'!N12 -> 1 | E9: ='PD Engine'!O12 -> 0.99627977 | F9: ='PD Engine'!P12 -> 1.0037202 | G9: ='LGD Analysis'!L27 -> 0.68034985 | H9: ='EAD Analysis'!L34 -> 1929080135 | J9: =H9*G9*D9 -> 1.3124494e+09 | K9: =H9*G9*E9 -> 1.3075668e+09 | L9: =H9*G9*F9 -> 1.317332e+09 | M9: =AVERAGE(J9:L9) -> 1.3124494e+09
J16: The above should be part of ECL analysis
J17: also coverga eratio
J18: CR = | K18: =M9/SUM('EAD Engine'!I7:I438) -> 0.21050429
